Workbook

Sheet DASHBOARD
A1: MOLINAS DATABASE DASHBOARD
A2: Executive view — Stakeholder, Regulatory, Policy & News Intelligence
A4: STAKEHOLDER | D4: P1 GATEKEEPER | E4: P2 SCALE ENABLER | F4: P3 SUPPORT | G4: REGULATORY ITEMS | J4: POLICY AREAS | M4: NEWS
A5: =COUNTA('MoLINas Integrated Plan'!B6:B37) -> 32 | D5: =COUNTIF('MoLINas Integrated Plan'!I6:I37,"P1") -> 14 | E5: =COUNTIF('MoLINas Integrated Plan'!I6:I37,"P2") -> 17 | F5: =COUNTIF('MoLINas Integrated Plan'!I6:I37,"P3") -> 1 | G5: =COUNTA('DASAR STAKEHOLDER & REGULASI'!A2:A215) -> 32 | J5: =COUNTA('USULAN & PERBANDINGAN'!A2:A13) -> 12 | M5: =COUNTA('DATABASE BERITA'!A2:A300) -> 130
A8: STAKEHOLDER LANDSCAPE | G8: POLICY & REGULATORY | K8: NEWS INTELLIGENCE
A9: Priority | B9: Jumlah | D9: Work Package | E9: Jumlah | G9: Indicator | H9: Value | K9: Segmen | L9: Jumlah | M9: Coverage | N9: Value
A10: P1 | B10: =COUNTIF('MoLINas Integrated Plan'!I6:I37,A10) -> 14 | D10: Hulu | E10: =COUNTIF('MoLINas Integrated Plan'!J6:J37,"*"&D10&"*") -> 11 | G10: Stakeholder / lembaga | H10: =COUNTA('DASAR STAKEHOLDER & REGULASI'!A2:A150) -> 32 | K10: Global | L10: =COUNTIF('DATABASE BERITA'!K:K,DASHBOARD!K10) -> 42 | M10: Countries | N10: =SUMPRODUCT(('DATABASE BERITA'!C2:C131<>"")/COUNTIF('DATABASE BERITA'!C2:C131,'DATABASE BERITA'!C2:C131&"")) -> 11
A11: P2 | B11: =COUNTIF('MoLINas Integrated Plan'!I6:I37,A11) -> 17 | D11: Midstream | E11: =COUNTIF('MoLINas Integrated Plan'!J6:J37,"*"&D11&"*") -> 4 | G11: Regulatory items | H11: =COUNTA('DASAR STAKEHOLDER & REGULASI'!B2:B150) -> 39 | K11: Lokal | L11: =COUNTIF('DATABASE BERITA'!K:K,DASHBOARD!K11) -> 31 | M11: Themes | N11: =SUMPRODUCT(('DATABASE BERITA'!F2:F131<>"")/COUNTIF('DATABASE BERITA'!F2:F131,'DATABASE BERITA'!F2:F131&"")) -> 23
A12: P3 | B12: =COUNTIF('MoLINas Integrated Plan'!I6:I37,A12) -> 1 | D12: Hilir | E12: =COUNTIF('MoLINas Integrated Plan'!J6:J37,"*"&D12&"*") -> 7 | G12: Policy areas | H12: =COUNTA('USULAN & PERBANDINGAN'!A2:A100) -> 12 | K12: Molinas | L12: =COUNTIF('DATABASE BERITA'!K:K,DASHBOARD!K12) -> 57 | M12: Latest | N12: =MAX('DATABASE BERITA'!B:B) -> 46274
D13: Enablers | E13: =COUNTIF('MoLINas Integrated Plan'!J6:J37,"*"&D13&"*") -> 10
A28: MOLINAS STRATEGIC AREAS — POLICY / ECOSYSTEM
A29: Area | E29: Key Direction | J29: R&D Priority
A30: ='USULAN & PERBANDINGAN'!B2 -> Mineral & Bahan Baku | E30: ='USULAN & PERBANDINGAN'!F2 -> Memperluas ekosistem KBLBB sampai upstream bahan baku strategis. Mengintegrasikan roadmap mineral kritis dengan baterai, hilirisasi, traceability, ketahanan pasok, efisiensi penggunaan material dan pengembangan material substitusi. | J30: ='USULAN & PERBANDINGAN'!H2 -> 10% dari total portofolio R&D KBLBB diarahkan pada refining, material baterai, precursor, material aktif, efisiensi material dan substitusi mineral kritis.
A31: ='USULAN & PERBANDINGAN'!B3 -> Baterai & Teknologi Baterai | E31: ='USULAN & PERBANDINGAN'!F3 -> Mengubah pendekatan dari battery component menjadi battery lifecycle ecosystem. Mencakup cell, module/pack, BMS, thermal management, safety, diagnostics/SOH, second-life, collection, recycling, recovery, traceability dan battery passport. | J31: ='USULAN & PERBANDINGAN'!H3 -> 20% dari portofolio R&D KBLBB untuk battery safety, fast charging, SOH/diagnostics, thermal management, LFP/NMC dan chemistry alternatif, second-life, recycling dan battery passport.
A32: ='USULAN & PERBANDINGAN'!B4 -> Powertrain & Komponen Elektrikal | E32: ='USULAN & PERBANDINGAN'!F4 -> Memperdalam lokalisasi teknologi inti powertrain, termasuk motor, inverter/controller, BMS, charger, power electronics dan komponen kritis; disertai supplier development dan transfer teknologi. | J32: ='USULAN & PERBANDINGAN'!H4 -> 20% untuk motor listrik, inverter/controller, semiconductor/power electronics, thermal management, control system dan system efficiency.
A33: ='USULAN & PERBANDINGAN'!B5 -> Chassis / Rangka & Komponen Kendaraan | E33: ='USULAN & PERBANDINGAN'!F5 -> Memperkuat domestic engineering & supplier capability untuk frame, suspension, steering, braking, wheel, body dan safety component. | J33: ='USULAN & PERBANDINGAN'!H5 -> 5% untuk lightweighting, structural engineering, crashworthiness, durability dan advanced material.
A34: ='USULAN & PERBANDINGAN'!B6 -> Manufaktur & Perakitan | E34: ='USULAN & PERBANDINGAN'!F6 -> Menjadikan fase CBU sebagai transisi menuju pendalaman manufaktur domestik. Dukungan dikaitkan dengan investasi, produksi, TKDN, supplier localization, transfer teknologi, tenaga kerja, R&D dan ekspor. | J34: ='USULAN & PERBANDINGAN'!H6 -> 15% untuk design engineering, process engineering, automation, quality system, manufacturing technology dan production digitalization.
A35: ='USULAN & PERBANDINGAN'!B7 -> Sertifikasi & Keselamatan Kendaraan | E35: ='USULAN & PERBANDINGAN'!F7 -> Memperluas assurance framework untuk EV dan software-defined vehicle, termasuk battery safety, functional safety, cybersecurity, OTA/software validation, SOH dan digital vehicle record. | J35: ='USULAN & PERBANDINGAN'!H7 -> 8% untuk testing/certification technology, battery safety, functional safety, cybersecurity, software validation dan interoperability.
A36: ='USULAN & PERBANDINGAN'!B8 -> Infrastruktur Pengisian & Ketenagalistrikan | E36: ='USULAN & PERBANDINGAN'!F8 -> Mengubah charging infrastructure menjadi integrated charging ecosystem: interoperability, roaming/payment, fast & ultrafast charging, load management, smart charging, renewable integration dan V2G. | J36: ='USULAN & PERBANDINGAN'!H8 -> 7% untuk smart charging, load management, V2G, grid integration, renewable-powered charging dan charging interoperability.
A37: ='USULAN & PERBANDINGAN'!B9 -> Konektivitas & Digital | E37: ='USULAN & PERBANDINGAN'!F9 -> Menambahkan digital/connected vehicle sebagai bagian formal ekosistem KBLBB, meliputi TCU/IoT, GPS/4G/5G, vehicle data, cybersecurity, OTA, digital vehicle record dan koneksi dengan battery passport. | J37: ='USULAN & PERBANDINGAN'!H9 -> 5% untuk vehicle data architecture, cybersecurity, OTA, telematics, AI/analytics dan digital records.
A38: ='USULAN & PERBANDINGAN'!B10 -> Fiskal, Perdagangan & Pembiayaan | E38: ='USULAN & PERBANDINGAN'!F10 -> Membentuk performance-based incentive framework: dukungan dikaitkan dengan TKDN, investasi, produksi, supplier lokal, tenaga kerja, R&D, ekspor dan kontribusi emisi; termasuk milestone, monitoring dan exit strategy. | J38: ='USULAN & PERBANDINGAN'!H10 -> 7% untuk matching fund, applied R&D, technology adoption, commercialization dan industrial research.
A39: ='USULAN & PERBANDINGAN'!B11 -> Lingkungan & Ekonomi Sirkular | E39: ='USULAN & PERBANDINGAN'!F11 -> Membangun battery circular economy framework, termasuk producer responsibility, collection, traceability, diagnosis, safe dismantling, second-life, recycling, recovery dan material recovery. | J39: ='USULAN & PERBANDINGAN'!H11 -> 3% untuk second-life, recycling efficiency, safe dismantling, material recovery dan circular design.
A40: ='USULAN & PERBANDINGAN'!B12 -> Pertahanan & Strategic Use Case | E40: ='USULAN & PERBANDINGAN'!F12 -> Membuka strategic/institutional pathway dalam ekosistem KBLBB, termasuk procurement, spesifikasi khusus, security requirement, lifecycle support dan keterlibatan industri strategis. | J40: ='USULAN & PERBANDINGAN'!H12 -> 3% untuk ruggedized EV, mission-specific battery/powertrain, secure communication, energy resilience dan defense-grade testing.
A41: ='USULAN & PERBANDINGAN'!B13 -> Program Strategis Nasional & Kelembagaan Lintas Sektor | E41: ='USULAN & PERBANDINGAN'!F13 -> Membangun National EV Ecosystem Governance: single data, KPI dashboard, roadmap lintas K/L, funding alignment, monitoring-evaluation dan periodic policy review. | J41: ='USULAN & PERBANDINGAN'!H13 -> 10% untuk national R&D portfolio, shared testing facility, technology readiness monitoring dan integrasi riset lintas kategori.
A44: LATEST NEWS — LINKED TO DATABASE BERITA
A45: Tanggal | B45: Negara | C45: Perusahaan / Brand | D45: Pilar Ekosistem | E45: Status | F45: Tema | G45: Media
A46: =IFERROR('DATABASE BERITA'!B2,"") -> 46274 | B46: =IFERROR('DATABASE BERITA'!C2,"") -> Indonesia | C46: =IFERROR('DATABASE BERITA'!D2,"") -> BKPM / Pemerintah | D46: =IFERROR('DATABASE BERITA'!E2,"") -> ENABLERS | E46: =IFERROR('DATABASE BERITA'!K2,"") -> Lokal | F46: =IFERROR('DATABASE BERITA'!F2,"") -> Charging / Swapping | G46: =IFERROR('DATABASE BERITA'!I2,"") -> ANTARA
A47: =IFERROR('DATABASE BERITA'!B3,"") -> 46273 | B47: =IFERROR('DATABASE BERITA'!C3,"") -> Indonesia | C47: =IFERROR('DATABASE BERITA'!D3,"") -> IBC / CATL | D47: =IFERROR('DATABASE BERITA'!E3,"") -> VALUE CHAIN (HULU–MIDSTREAM–HILIR) | E47: =IFERROR('DATABASE BERITA'!K3,"") -> MoLiNas | F47: =IFERROR('DATABASE BERITA'!F3,"") -> HULU — Battery & Components | G47: =IFERROR('DATABASE BERITA'!I3,"") -> Bisnis.com
A48: =IFERROR('DATABASE BERITA'!B4,"") -> 46270 | B48: =IFERROR('DATABASE BERITA'!C4,"") -> Indonesia | C48: =IFERROR('DATABASE BERITA'!D4,"") -> Pemerintah / MoLiNas | D48: =IFERROR('DATABASE BERITA'!E4,"") -> REGULATORY & POLICY | E48: =IFERROR('DATABASE BERITA'!K4,"") -> MoLiNas | F48: =IFERROR('DATABASE BERITA'!F4,"") -> Regulasi, Kebijakan & Insentif | G48: =IFERROR('DATABASE BERITA'!I4,"") -> ITERA
A49: =IFERROR('DATABASE BERITA'!B5,"") -> 46270 | B49: =IFERROR('DATABASE BERITA'!C5,"") -> Indonesia | C49: =IFERROR('DATABASE BERITA'!D5,"") -> DPR RI / BYD | D49: =IFERROR('DATABASE BERITA'!E5,"") -> REGULATORY & POLICY | E49: =IFERROR('DATABASE BERITA'!K5,"") -> Lokal | F49: =IFERROR('DATABASE BERITA'!F5,"") -> TKDN & Sertifikasi | G49: =IFERROR('DATABASE BERITA'!I5,"") -> DPR RI
A50: =IFERROR('DATABASE BERITA'!B6,"") -> 46270 | B50: =IFERROR('DATABASE BERITA'!C6,"") -> Indonesia | C50: =IFERROR('DATABASE BERITA'!D6,"") -> BYD | D50: =IFERROR('DATABASE BERITA'!E6,"") -> REGULATORY & POLICY | E50: =IFERROR('DATABASE BERITA'!K6,"") -> Lokal | F50: =IFERROR('DATABASE BERITA'!F6,"") -> TKDN & Sertifikasi | G50: =IFERROR('DATABASE BERITA'!I6,"") -> OtoDream

Sheet MoLINas Integrated Plan
A1: MOLINAS – INTEGRATED STAKEHOLDER, REGULATORY, PIC & GANTT SCHEDULE
AB2: PHASE 0 (2026) Penetrasi Pasar & Penetapan Komponen Utama | AP2: STATUS STAKEHOLDER
A3: STAKEHOLDER & REGULATORY | Q3: ENGAGEMENT & GOVERNANCE | AB3: WEEKLY GANTT – 2026
Y4: AUGUST 2026 | Z4: SEPTEMBER 2026 | AD4: OCTOBER 2026 | AH4: NOVEMBER 2026 | AL4: DECEMBER 2026 | AP4: STATUS | AQ4: Engagement Status | AR4: Last Engagement / Update | AS4: Follow-Up / Commitment | AT4: Relationship Status
A5: No | B5: Stakeholder / Lembaga | C5: Kategori / Isu Utama | D5: Criticality (1–5) | E5: Breadth of Impact (1–5) | F5: Dependency (1–5) | G5: Urgency (1–5) | H5: Weighted Score | I5: Prioritas | J5: Domain Ekosistem | K5: Isu | L5: Contoh Regulasi Utama / Dasar | M5: Ruang Lingkup | N5: Terkait Tahap Ekosistem | O5: Ecosystem Value Chain Layer | P5: Cross-Cutting Enabler | Q5: Agenda Engagement | R5: Lead PIC (WS) | S5: Supporting PIC | T5: BOD Accountable | U5: PD/PMO | V5: Peran Danantara | W5: ALVA / Mitra | X5: Target Outcome | Y5: Agt W1 | Z5: Sep W1 | AA5: Sep W2 | AB5: Sep W3 | AC5: Sep W4 | AD5: Okt W1 | AE5: Okt W2 | AF5: Okt W3 | AG5: Okt W4 | AH5: Nov W1 | AI5: Nov W2 | AJ5: Nov W3 | AK5: Nov W4 | AL5: Des W1 | AM5: Des W2 | AN5: Des W3 | AO5: Des W4
A6: 1 | B6: BRIN (Connector Charger) | C6: R&D / technology development | D6: 5 | E6: 4 | F6: 4 | G6: 4 | H6: =(D6*$B$56)+(E6*$B$57)+(F6*$B$58)+(G6*$B$59) -> 4.3 | I6: =IF(H6>=4.25,"P1",IF(H6>=3,"P2","P3")) -> P1 | J6: Midstream | K6: Baterai & Teknologi Baterai; Powertrain & Komponen Elektrikal | L6: SNI baterai & keselamatan; SNI komponen kelistrikan | M6: Riset, pengembangan, validasi teknologi baterai, motor listrik, controller, inverter, BMS dan komponen | N6: Bahan Baku & Komponen Dasar; Infrastruktur & Pendukung | O6: 1. Engineering, Technology & R&D; 2. Raw Materials & Components; 7. Infrastructure & Charging | P6: Technology, Data & Digital | Q6: R&D / technology development | R6: WS3 – Innovation | S6: WS2 Ecosystem; WS2 Legal | T6: CTO | U6: Monitoring | V6: Support | W6: Technical partner | X6: Technology validation & collaboration | Z6: Audiensi | AA6: Audiensi | AB6: Riset & kolaborasi teknologi | AC6: Riset & kolaborasi teknologi | AD6: Scope alignment | AE6: Validasi teknologi | AF6: Validasi teknologi | AG6: Validasi teknologi | AH6: Dukungan pengembangan | AI6: Dukungan pengembangan | AJ6: Dukungan pengembangan | AK6: Dukungan pengembangan | AL6: Monitoring | AM6: Monitoring | AN6: Monitoring | AO6: Monitoring | AP6: In Progress | AQ6: Ongoing | AR6: 46289 | AS6: Continue technical discussion on connector, charging interface, research results, standardization direction and potential application in MOLINAS. | AT6: Active
A7: 2 | B7: IBC | C7: Teknologi & Baterai | D7: 5 | E7: 5 | F7: 5 | G7: 4 | H7: =(D7*$B$56)+(E7*$B$57)+(F7*$B$58)+(G7*$B$59) -> 4.75 | I7: =IF(H7>=4.25,"P1",IF(H7>=3,"P2","P3")) -> P1 | J7: Hulu | K7: Battery Cell | M7: Produksi battery cell domestik, kapasitas manufaktur, yield, quality, local input, dan keterhubungan dengan OEM | N7: Manufaktur & Supply Chain ; Bahan Baku & Komponen Dasar | O7: 2. Raw Materials & Components; 3. Manufacturing & Assembly; 4. Supply Chain & Logistics | Q7: Cell manufacturing / industrialization & ecosystem integration | R7: WS2 – Ecosystem | S7: WS3 – Innovation, Supply Chain | T7: CMO | U7: Monitoring | V7: Support | W7: Partner input | X7: Kesiapan dan scale-up produksi battery cell domestik serta integrasi dengan OEM | Z7: Audiensi / engagement awal | AA7: Audiensi / engagement awal | AB7: Pembahasan kebutuhan produk & OEM | AC7: Diskusi awal | AD7: Alignment deployment | AE7: Koordinasi uji coba | AF7: Koordinasi uji coba | AG7: Koordinasi uji coba | AH7: Koordinasi implementasi fleet/deployment | AI7: Koordinasi implementasi fleet/deployment | AJ7: Koordinasi implementasi fleet/deployment | AK7: Koordinasi implementasi fleet/deployment | AL7: Monitoring | AM7: Monitoring | AN7: Monitoring | AO7: Monitoring | AP7: In Progress | AQ7: Ongoing | AR7: 46289 | AS7: Continue battery standardization and alignment on battery specifications, supply readiness and OEM integration. | AT7: Active
A8: 3 | B8: ALVA (Mitra / OEM) | C8: OEM collaboration | D8: 4 | E8: 5 | F8: 5 | G8: 4 | H8: =(D8*$B$56)+(E8*$B$57)+(F8*$B$58)+(G8*$B$59) -> 4.45 | I8: =IF(H8>=4.25,"P1",IF(H8>=3,"P2","P3")) -> P1 | J8: Hulu | K8: Mitra / OEM | L8: Ketentuan industri/manufaktur dan partnership yang relevan | M8: OEM collaboration, partnership structure, technical/commercial input | N8: Manufaktur & Supply Chain; Distribusi & Pasar | O8: 3. Manufacturing & Assembly; 4. Supply Chain & Logistics; 5. Sales, Distribution & Market | Q8: OEM collaboration | R8: WS1 – Business Development | S8: WS3 Marketing, Supply Chain; WS4 Finance, WS2 Ecosystem | T8: CMO | U8: Monitoring | V8: Accompany | W8: Partner / OEM | X8: Partnership structure & commitment | Z8: Audiensi / engagement awal | AA8: Audiensi / engagement awal | AB8: Pembahasan kebutuhan produk & OEM | AC8: Alignment kebutuhan fleet / armada | AD8: Alignment kebutuhan fleet / armada | AE8: Alignment komersial & deployment | AF8: Koordinasi uji coba | AG8: Koordinasi uji coba | AH8: Koordinasi implementasi fleet | AI8: Koordinasi implementasi fleet | AJ8: Koordinasi deployment | AK8: Koordinasi deployment | AL8: Monitoring engagement | AM8: Monitoring engagement | AN8: Monitoring engagement | AO8: Monitoring engagement | AP8: In Progress | AQ8: Ongoing | AR8: 46289 | AS8: Continue OEM/product discussion, including technical specifications, production readiness, market segmentation and partnership alignment. | AT8: Active
A9: 4 | B9: GESITS (Mitra / OEM) | C9: OEM collaboration | D9: 4 | E9: 5 | F9: 5 | G9: 4 | H9: =(D9*$B$56)+(E9*$B$57)+(F9*$B$58)+(G9*$B$59) -> 4.45 | I9: =IF(H9>=4.25,"P1",IF(H9>=3,"P2","P3")) -> P1 | J9: Hulu | K9: Mitra / OEM | L9: Ketentuan industri/manufaktur dan partnership yang relevan | M9: OEM collaboration, partnership structure, technical/commercial input | N9: Manufaktur & Supply Chain; Distribusi & Pasar | O9: 3. Manufacturing & Assembly; 4. Supply Chain & Logistics; 5. Sales, Distribution & Market | Q9: OEM collaboration | R9: WS1 – Business Development | S9: WS3 Marketing, Supply Chain; WS4 Finance, WS2 Ecosystem | T9: CMO | U9: Monitoring | V9: Accompany | W9: Partner / OEM | X9: Partnership structure & commitment | Y9: Partner / OEM mapping | Z9: Audiensi / engagement awal | AA9: Audiensi / engagement awal | AB9: Pembahasan kebutuhan produk & OEM | AC9: Alignment kebutuhan fleet / armada | AD9: Alignment kebutuhan fleet / armada | AE9: Alignment komersial & deployment | AF9: Koordinasi uji coba | AG9: Koordinasi uji coba | AH9: Koordinasi implementasi fleet | AI9: Koordinasi implementasi fleet | AJ9: Koordinasi deployment | AK9: Koordinasi deployment | AL9: Monitoring engagement | AM9: Monitoring engagement | AN9: Monitoring engagement | AO9: Monitoring engagement | AP9: In Progress | AQ9: Ongoing | AR9: 46289 | AS9: Continue OEM/product discussion, including technical specifications, production readiness, battery/brick alignment and partnership alignment. | AT9: Active
A10: 5 | B10: GESITS (Teknologi) | C10: Teknologi & Baterai | D10: 5 | E10: 4 | F10: 4 | G10: 4 | H10: =(D10*$B$56)+(E10*$B$57)+(F10*$B$58)+(G10*$B$59) -> 4.3 | I10: =IF(H10>=4.25,"P1",IF(H10>=3,"P2","P3")) -> P1 | J10: Hulu | K10: Baterai & Teknologi Baterai | M10: BRICK - jenis baterai yang dikembangkan/dimiliki GESITS | N10: Bahan Baku & Komponen Dasar; | O10: 1. Engineering, Technology & R&D; 2. Raw Materials & Components | P10: Technology, Data & Digital | Q10: Standardisasi tipe baterai | R10: WS3 – Innovation | S10: WS2 Ecosystem; WS4 Finance | T10: CTO | U10: Monitoring | V10: Co-Lead | W10: Partner input | X10: Alignment dan integrasi teknologi BRICK dalam ekosistem baterai MoLiNas | Z10: Stakeholder engagement | AA10: Regulatory alignment | AB10: Regulatory alignment | AC10: Regulatory alignment | AD10: Ecosystem coordination | AE10: Ecosystem coordination | AF10: Ecosystem coordination | AG10: Ecosystem coordination | AH10: Partnership / deployment pathway | AI10: Partnership / deployment pathway | AJ10: Partnership / deployment pathway | AK10: Partnership / deployment pathway | AL10: Monitoring | AM10: Monitoring | AN10: Monitoring | AO10: Monitoring | AP10: In Progress | AQ10: Ongoing | AR10: 46289 | AS10: Continue battery standardization discussion and alignment of GESITS battery technology/BRICK with MOLINAS requirements. | AT10: Active
A11: 6 | B11: Kemenperin | C11: 1. Regulatory, TKDN, industrial regulation 2. OEM, manufaktur & supply chain | D11: 5 | E11: 5 | F11: 5 | G11: 5 | H11: =(D11*$B$56)+(E11*$B$57)+(F11*$B$58)+(G11*$B$59) -> 5 | I11: =IF(H11>=4.25,"P1",IF(H11>=3,"P2","P3")) -> P1 | J11: Hulu | K11: 1. Baterai & Teknologi Baterai 2. Powertrain & Komponen Elektrikal; Manufaktur & Perakitan | L11: 1. Permenperin No. 28/2023 (TKDN KLBB); Permenperin No. 35/2025 (Sertifikasi TKDN & BMP); SNI baterai & keselamatan; Regulasi lembaga penilai (Permen LHK No. 9/2024) 2. Permenperin No. 28/2023; Permenperin No. 35/2023; SNI komponen kelistrikan; Permenperin No. 29/2023 (Industri KBLBB); Permenperin No. 35/2023; Permenperin No. 38/2023 | M11: 1. Produksi/impor baterai, TKDN, standardisasi (SNI), keselamatan, pengelolaan baterai bekas, riset & pengembangan teknologi 2. Motor listrik, controller, inverter, BMS, komponen utama/pendukung; industri kendaraan listrik, perakitan OEM/IKD/CKD, TKDN, sertifikasi industri, fasilitas produksi | N11: Bahan Baku & Komponen Dasar; Manufaktur & Supply Chain; Daur Ulang & Ekosistem Sirkular | O11: 1. Engineering, Technology & R&D; 2. Raw Materials & Components; 3. Manufacturing & Assembly; 4. Supply Chain & Logistics; 9. Circular Economy & Recycling | P11: Policy, Regulation & Standards; Technology, Data & Digital | Q11: 1. Regulatory, TKDN, industrial regulation 2. OEM, manufaktur & supply chain | R11: WS2 – Legal | S11: 1. WS2 Ecosystem; WS3 Innovation, Supply Chain 2. WS3 Supply Chain, Innovation; WS2 Legal | T11: 1. CTO 2. COO | U11: Monitoring | V11: 1. Accompany / Co-Lead 2. Accompany | W11: 1. Technical input 2. OEM/industry input | X11: 1. Regulatory pathway & TKDN clear 2. Production & industrialization roadmap | Z11: Audiensi awal | AA11: Audiensi awal | AB11: Pembahasan regulasi & TKDN | AC11: Pembahasan regulasi & TKDN | AD11: Alignment akhir | AE11: Finalisasi TKDN & manufaktur | AF11: Finalisasi TKDN & manufaktur | AG11: Finalisasi TKDN & manufaktur | AH11: Implementasi & monitoring | AI11: Implementasi & monitoring | AJ11: Implementasi & monitoring | AK11: Implementasi & monitoring | AL11: Monitoring | AM11: Monitoring | AN11: Monitoring | AO11: Monitoring | AP11: In Progress | AQ11: Planned | AS11: Map and schedule engagement with Kemenperin to discuss regulatory pathway, TKDN, industrial regulation, OEM, manufacturing and supply-chain readiness. | AT11: Need Follow Up
A12: 7 | B12: Kemenhub | C12: Uji tipe, SUT, SRUT, kelaikan | D12: 5 | E12: 4 | F12: 5 | G12: 5 | H12: =(D12*$B$56)+(E12*$B$57)+(F12*$B$58)+(G12*$B$59) -> 4.8 | I12: =IF(H12>=4.25,"P1",IF(H12>=3,"P2","P3")) -> P1 | J12: Hulu | K12: Sertifikasi Kendaraan (Uji Tipe, SUT, SRUT); Chassis/Rangka & Komponen Kendaraan | L12: Permenhub No. 87/2020 (Uji Tipe KLBB); Permenhub No. 44/2020 jo. 86/2020 (Pengujian tipe kendaraan listrik); Ketentuan SUT & SRUT; Permenperin No. 28/2023; Ketentuan keselamatan kendaraan (Kemenhub) | M12: Uji tipe, homologasi, SUT (TIPE), SRUT (produksi), registrasi, keselamatan & kelaikan jalan; rangka, suspensi, rem, roda, body, keselamatan & kelaikan teknis | N12: Manufaktur & Supply Chain; Distribusi & Pasar; Pengguna & Layanan | O12: 2. Raw Materials & Components; 3. Manufacturing & Assembly; 4. Supply Chain & Logistics; 5. Sales, Distribution & Market; 6. User, Service & After-Sales | P12: Policy, Regulation & Standards | Q12: Uji tipe, SUT, SRUT, kelaikan | R12: WS2 – Legal | S12: WS3 Innovation; WS2 Ecosystem | T12: CTO | U12: Monitoring | V12: Accompany | W12: Vehicle/OEM support | X12: Certification pathway (type approval) | Z12: Audiensi awal | AA12: Audiensi awal | AB12: Uji tipe, SUT, SRUT | AC12: Uji tipe, SUT, SRUT | AD12: Alignment persyaratan | AE12: Finalisasi regulasi & standar teknis | AF12: Finalisasi regulasi & standar teknis | AG12: Finalisasi regulasi & standar teknis | AH12: Sertifikasi & compliance | AI12: Sertifikasi & compliance | AJ12: Sertifikasi & compliance | AK12: Sertifikasi & compliance | AL12: Monitoring | AM12: Monitoring | AN12: Monitoring | AO12: Monitoring | AP12: Pending | AQ12: Planned | AS12: Schedule engagement to clarify type approval, SUT, SRUT and vehicle roadworthiness pathway. | AT12: Need Follow Up
A13: 8 | B13: Kemenkeu | C13: Fiskal & insentif KLBB | D13: 5 | E13: 4 | F13: 4 | G13: 4 | H13: =(D13*$B$56)+(E13*$B$57)+(F13*$B$58)+(G13*$B$59) -> 4.3 | I13: =IF(H13>=4.25,"P1",IF(H13>=3,"P2","P3")) -> P1 | J13: Enablers (Financing & Support) | K13: Fiskal, Perdagangan & Pembiayaan | L13: PMK insentif KBLBB (PPN, PPnBM, bea masuk, dll); Ketentuan perdagangan/impor-ekspor; POJK pembiayaan & leasing | M13: Insentif fiskal, bea masuk, perdagangan, pembiayaan konsumen & fleet, skema leasing, green financing | N13: Distribusi & Pasar; Pengguna & Layanan | O13: 5. Sales, Distribution & Market; 6. User, Service & After-Sales; 8. Financing & Investment | Q13: Fiskal & insentif KLBB | R13: WS4 – Finance | S13: WS2 Legal; WS1 Business Development | T13: CFO | U13: Monitoring | V13: Co-Lead | W13: - | X13: Fiscal / incentive framework clarity | Z13: Diskusi insentif & skema fiskal | AA13: Diskusi insentif & skema fiskal | AB13: Diskusi insentif & skema fiskal | AC13: Diskusi insentif & skema fiskal | AD13: Penyelarasan skema | AE13: Finalisasi skema | AF13: Finalisasi skema | AG13: Finalisasi skema | AH13: Implementasi insentif | AI13: Implementasi insentif | AJ13: Implementasi insentif | AK13: Implementasi insentif | AL13: Evaluasi | AM13: Evaluasi | AN13: Evaluasi | AO13: Evaluasi | AP13: In Progress | AQ13: Completed | AR13: 46280 | AS13: Continue follow-up on fiscal/incentive framework and inputs from the Kemenkeu FGD. | AT13: Need Follow Up
A14: 9 | B14: Bappenas (Pihak terkait: KPPII) | C14: Perencanaan nasional / PSN | D14: 5 | E14: 4 | F14: 4 | G14: 4 | H14: =(D14*$B$56)+(E14*$B$57)+(F14*$B$58)+(G14*$B$59) -> 4.3 | I14: =IF(H14>=4.25,"P1",IF(H14>=3,"P2","P3")) -> P1 | J14: Hulu | K14: Program Strategis Nasional (PSN) & Kelembagaan Lintas Sektor | L14: PP No. 42/2021 (PSN); Permenko Perekonomian No. 20/2025 (Rencana & evaluasi PSN); Regulasi terkait penugasan BUMN | M14: Koordinasi lintas K/L, penetapan/status PSN, sinkronisasi program, pendanaan, monitoring & evaluasi | N14: Semua Tahap (Ekosistem) | O14: Perlu validasi | P14: Governance & Institutional Support | Q14: Strategic program / PSN | R14: WS1 – Business Development | S14: WS1 Corporate Strategic Planning; WS2 Legal/Ecosystem; WS4 Finance | T14: CEO / CMO | U14: Monitoring | V14: Co-Lead | W14: - | X14: National program alignment & support framework | Z14: Audiensi & strategic alignment | AA14: Audiensi & strategic alignment | AB14: Audiensi & strategic alignment | AC14: Dukungan program nasional | AD14: Framework dukungan | AE14: Framework dukungan | AF14: Framework dukungan | AG14: Framework dukungan | AH14: Koordinasi implementasi | AI14: Koordinasi implementasi | AJ14: Koordinasi implementasi | AK14: Koordinasi implementasi | AL14: Monitoring | AM14: Monitoring | AN14: Monitoring | AO14: Monitoring | AP14: In Progress | AQ14: Completed | AR14: 46265 | AS14: Follow up strategic program / PSN alignment and support framework. | AT14: Need Follow Up
A15: 10 | B15: ESDM | C15: Mineral & hilirisasi | D15: 5 | E15: 4 | F15: 5 | G15: 4 | H15: =(D15*$B$56)+(E15*$B$57)+(F15*$B$58)+(G15*$B$59) -> 4.55 | I15: =IF(H15>=4.25,"P1",IF(H15>=3,"P2","P3")) -> P1 | J15: Hulu | K15: Mineral & Bahan Baku | L15: UU No. 3/2020 (Mineral dan Batubara); PP No. 25/2024 (Perubahan atas PP 96/2021); Peraturan turunannya (RKAB, hilirisasi, dll) | M15: Pasokan mineral kritis (nikel, kobalt, mangan, lithium), hilirisasi, perizinan tambang, rantai pasok bahan baku | N15: Bahan Baku & Komponen Dasar | O15: 2. Raw Materials & Components | Q15: Mineral & hilirisasi | R15: WS2 – Ecosystem | S15: WS2 Legal; WS3 Supply Chain, Innovation | T15: CTO | U15: Monitoring | V15: Accompany | W15: - | X15: Mineral supply & hilirisasi alignment | Z15: Mineral & hilirisasi (baterai) | AA15: Mineral & hilirisasi (baterai) | AB15: Mineral & hilirisasi (baterai) | AC15: Supply chain alignment | AD15: Kepastian pasokan & rantai pasok | AE15: Kepastian pasokan & rantai pasok | AF15: Kepastian pasokan & rantai pasok | AG15: Kepastian pasokan & rantai pasok | AH15: Implementasi rantai pasok | AI15: Implementasi rantai pasok | AJ15: Implementasi rantai pasok | AK15: Implementasi rantai pasok | AL15: Monitoring | AM15: Monitoring | AN15: Monitoring | AO15: Monitoring | AP15: Pending | AQ15: Planned | AS15: Schedule engagement on mineral supply and downstreaming alignment for battery ecosystem. | AT15: Need Follow Up
A16: 11 | B16: Kemenhan | C16: Strategic / defense use case | D16: 5 | E16: 4 | F16: 4 | G16: 4 | H16: =(D16*$B$56)+(E16*$B$57)+(F16*$B$58)+(G16*$B$59) -> 4.3 | I16: =IF(H16>=4.25,"P1",IF(H16>=3,"P2","P3")) -> P1 | J16: Hilir | K16: Pertahanan & Strategic Use Case | L16: UU No. 16/2012 (Industri Pertahanan); kebijakan pengadaan TNI, standar militer terkait | M16: Kebutuhan TNI, spesifikasi militer, kelaikan pertahanan, procurement & deployment, dukungan industri strategis | N16: Pengguna & Layanan | O16: 4. Supply Chain & Logistics; 6. User, Service & After-Sales | P16: Policy, Regulation & Standards | Q16: Strategic / defense use case | R16: WS3 – Market & Sales | S16: WS2 Ecosystem, Legal; WS3 Innovation | T16: CMO | U16: Monitoring | V16: Accompany | W16: - | X16: Defense use case & demand alignment | Z16: Kebutuhan TNI & use case | AA16: Kebutuhan TNI & use case | AB16: Kebutuhan TNI & use case | AC16: Requirement & spesifikasi | AD16: Requirement freeze | AE16: Validasi use case | AF16: Validasi use case | AG16: Validasi use case | AH16: Pengadaan & implementasi | AI16: Pengadaan & implementasi | AJ16: Pengadaan & implementasi | AK16: Pengadaan & implementasi | AL16: Monitoring | AM16: Monitoring | AN16: Monitoring | AO16: Monitoring | AP16: In Progress | AQ16: Completed | AR16: 46280 | AS16: Follow up defense use case, demand requirements and strategic alignment discussed with Kemhan. | AT16: Need Follow Up
A17: 12 | B17: TNI / Defense User | C17: Requirement & demand | D17: 5 | E17: 4 | F17: 4 | G17: 4 | H17: =(D17*$B$56)+(E17*$B$57)+(F17*$B$58)+(G17*$B$59) -> 4.3 | I17: =IF(H17>=4.25,"P1",IF(H17>=3,"P2","P3")) -> P1 | J17: Hilir | K17: Pertahanan & Strategic Use Case | L17: Kebijakan pengadaan TNI dan kebutuhan user | M17: User requirement, demand, spesifikasi, procurement/use case | N17: Pengguna & Layanan | O17: 4. Supply Chain & Logistics; 6. User, Service & After-Sales | Q17: Requirement & demand | R17: WS3 – Market & Sales | S17: WS2 Ecosystem; WS3 Innovation | T17: CMO | U17: Monitoring | V17: Accompany | W17: - | X17: User requirement / demand commitment | Z17: Diskusi kebutuhan awal | AA17: Diskusi kebutuhan awal | AB17: Diskusi kebutuhan awal | AC17: Procurement & spesifikasi | AD17: Alignment | AE17: Validasi produk | AF17: Validasi produk | AG17: Validasi produk | AH17: Uji operasional & feedback | AI17: Uji operasional & feedback | AJ17: Uji operasional & feedback | AK17: Uji operasional & feedback | AL17: Monitoring | AM17: Monitoring | AN17: Monitoring | AO17: Monitoring | AP17: Pending | AQ17: Planned | AS17: Engage defense users to validate requirements and potential demand commitment. | AT17: Need Follow Up
A18: 13 | B18: Dirjen Pothan | C18: Pertahanan & Strategic use case | D18: 5 | E18: 4 | F18: 4 | G18: 4 | H18: =(D18*$B$56)+(E18*$B$57)+(F18*$B$58)+(G18*$B$59) -> 4.3 | I18: =IF(H18>=4.25,"P1",IF(H18>=3,"P2","P3")) -> P1 | J18: Midstream | K18: Pertahanan & Strategic use case | M18: Alignment kebutuhan pertahanan, user requirement, spesifikasi, kelaikan, procurement dan peluang deployment kendaraan listrik untuk strategic use case | N18: Pengguna & Layanan | O18: 4. Supply Chain & Logistics; 6. User, Service & After-Sales | P18: Policy, Regulation & Standards | Q18: Strategic defense engagement, requirement & demand alignment | R18: WS3 – Market & Sales | S18: WS3 Innovation; WS3 Market & Sales; WS2 Ecosystem | T18: CMO | U18: Monitoring | V18: Co-Lead | W18: Partner Input | X18: Defense use case alignment, requirement definition & strategic procurement pathway | Z18: Audiensi / engagement awal | AA18: Audiensi / engagement awal | AB18: Kebutuhan & strategic use case | AC18: Kebutuhan & strategic use case | AD18: Requirement alignment | AE18: Validasi use case | AF18: Validasi use case | AG18: Validasi use case | AH18: Procurement / deployment pathway | AI18: Procurement / deployment pathway | AJ18: Procurement / deployment pathway | AK18: Procurement / deployment pathway | AL18: Monitoring | AM18: Monitoring | AN18: Monitoring | AO18: Monitoring | AP18: In Progress | AQ18: Completed | AR18: 46266 | AS18: Follow up defense use case, requirements and strategic procurement pathway after Dirjen Pothan engagement. | AT18: Need Follow Up
A19: 14 | B19: Danantara | C19: Financing ecosystem | D19: 5 | E19: 5 | F19: 5 | G19: 4 | H19: =(D19*$B$56)+(E19*$B$57)+(F19*$B$58)+(G19*$B$59) -> 4.75 | I19: =IF(H19>=4.25,"P1",IF(H19>=3,"P2","P3")) -> P1 | J19: Enablers (Financing & Support) | K19: Fiskal, Perdagangan & Pembiayaan, Program/investment/strategic partnership alignment | M19: Mandat pengelolaan dan optimalisasi investasi pemerintah/aset BUMN, tata kelola Danantara, serta pengelolaan aset; relevan untuk alignment investasi strategis dan dukungan ekosistem pembiayaan MOLINAS. | N19: Distribusi & Pasar; Pengguna & Layanan ; Manufaktur & Supply Chain; | O19: 3. Manufacturing & Assembly; 4. Supply Chain & Logistics; 5. Sales, Distribution & Market; 6. User, Service & After-Sales; 8. Financing & Investment | P19: Governance & Institutional Support | Q19: Financing ecosystem | R19: WS1 – Business Development | S19: WS2 – Ecosystem; WS4 – Finance; WS2 – Legal | T19: CTO/CMO | U19: Monitoring | V19: Co-Lead | W19: Optional | X19: Financing pathway & strategic investment alignment | AB19: Diskusi insentif & skema fiskal | AC19: Diskusi insentif & skema fiskal | AD19: Penyelarasan skema | AE19: Finalisasi skema | AF19: Finalisasi skema | AG19: Finalisasi skema | AH19: Implementasi insentif | AI19: Implementasi insentif | AJ19: Implementasi insentif | AK19: Implementasi insentif | AL19: Evaluasi | AM19: Evaluasi | AN19: Evaluasi | AO19: Evaluasi | AP19: In Progress | AQ19: Ongoing | AR19: 46289 | AS19: Continue coordination with Danantara/DDMF on timeline, budget needs, Pra-FS/FS scope and financing/program alignment. | AT19: Active
A20: 15 | B20: Himbara (Bank Mandiri, BRI BNI, BTN, BSI) | C20: Financing ecosystem | D20: 4 | E20: 4 | F20: 4 | G20: 3 | H20: =(D20*$B$56)+(E20*$B$57)+(F20*$B$58)+(G20*$B$59) -> 3.75 | I20: =IF(H20>=4.25,"P1",IF(H20>=3,"P2","P3")) -> P2 | J20: Enablers (Financing & Support) | K20: Fiskal, Perdagangan & Pembiayaan | L20: POJK pembiayaan & leasing; Ketentuan pembiayaan konsumen/fleet, green financing | M20: Pembiayaan konsumen & fleet, skema leasing, green financing, market access | N20: Distribusi & Pasar; Pengguna & Layanan | O20: 5. Sales, Distribution & Market; 6. User, Service & After-Sales; 8. Financing & Investment | Q20: Financing ecosystem | R20: WS4 – Finance | S20: WS2 Legal; WS3 Market & Sales | T20: CFO | U20: Monitoring | V20: Co-Lead | W20: Optional | X20: Financing scheme & market readiness | Z20: Diskusi awal | AA20: Diskusi awal | AB20: Skema pembiayaan | AC20: Skema pembiayaan | AD20: Alignment pembiayaan | AE20: Finalisasi skema | AF20: Finalisasi skema | AG20: Finalisasi skema | AH20: Implementasi & market access | AI20: Implementasi & market access | AJ20: Implementasi & market access | AK20: Implementasi & market access | AL20: Monitoring | AM20: Monitoring | AN20: Monitoring | AO20: Monitoring | AP20: In Progress | AQ20: Planned | AS20: Finalize and conduct financing discussion with Himbara on B2B financing scheme and market readiness. | AT20: Need Follow Up
A21: 16 | B21: Kemenaker | C21: Ketenagakerjaan dan Pengembangan SDM | D21: 4 | E21: 4 | F21: 4 | G21: 4 | H21: =(D21*$B$56)+(E21*$B$57)+(F21*$B$58)+(G21*$B$59) -> 4 | I21: =IF(H21>=4.25,"P1",IF(H21>=3,"P2","P3")) -> P2 | J21: Enablers (Logistics & SDM) | K21: Manufaktur & Perakitan, Ecosystem/capability/SDM | M21: Kebutuhan & penyerapan tenaga kerja, pengembangan kompetensi, pelatihan/upskilling-reskilling, sertifikasi tenaga kerja, serta kesiapan SDM untuk mendukung industrialisasi motor listrik nasional. | N21: Semua Tahap (Ekosistem) | O21: 3. Manufacturing & Assembly | P21: Policy, Regulation & Standards; Human Capital & Capability | Q21: Kebutuhan tenaga kerja, kompetensi, pelatihan, sertifikasi & penyerapan tenaga kerja | R21: WS2 – Ecosystem | S21: WS3 – Innovation & Operation; WS2 – Ecosystem | T21: CTO/CMO | U21: Monitoring | V21: Accompany | W21: - | X21: Workforce readiness & employment creation | Z21: Audiensi & strategic alignment | AA21: Audiensi & strategic alignment | AB21: Audiensi & strategic alignment | AC21: Audiensi & strategic alignment | AD21: Aligntment | AE21: Framework dukungan | AF21: Framework dukungan | AG21: Framework dukungan | AH21: Implementasi Insentif | AI21: Implementasi insentif | AJ21: Implementasi insentif | AK21: Implementasi insentif | AL21: Monitoring | AM21: Monitoring | AN21: Monitoring | AO21: Monitoring | AP21: Pending | AQ21: Planned | AS21: Schedule engagement on workforce requirements, competencies, training, certification and employment absorption. | AT21: Need Follow Up
A22: 17 | B22: PLN | C22: Charging & ketenagalistrikan | D22: 4 | E22: 4 | F22: 4 | G22: 3 | H22: =(D22*$B$56)+(E22*$B$57)+(F22*$B$58)+(G22*$B$59) -> 3.75 | I22: =IF(H22>=4.25,"P1",IF(H22>=3,"P2","P3")) -> P2 | J22: Enablers (Charging / Swapping) | K22: Infrastruktur Pengisian & Ketenagalistrikan | L22: Permen ESDM No. 1/2023 (SPKLU); Ketentuan ketenagalistrikan, tarif, K3 | M22: SPKLU/SPBKLU, tarif listrik, integrasi jaringan, standar teknis & keselamatan | N22: Distribusi & Pasar; Pengguna & Layanan | O22: 5. Sales, Distribution & Market; 6. User, Service & After-Sales; 7. Infrastructure & Charging | P22: Policy, Regulation & Standards | Q22: Charging & ketenagalistrikan | R22: WS3 – Innovation | S22: WS3 Supply Chain; WS2 Legal/Ecosystem | T22: CTO / COO | U22: Monitoring | V22: Accompany | W22: Technical input | X22: Charging infrastructure pathway | Z22: Mineral & hilirisasi (baterai) | AA22: Mineral & hilirisasi (baterai) | AB22: Mineral & hilirisasi (baterai) | AC22: Supply chain alignment | AD22: Kepastian pasokan & rantai pasok | AE22: Kepastian pasokan & rantai pasok | AF22: Kepastian pasokan & rantai pasok | AG22: Kepastian pasokan & rantai pasok | AH22: Implementasi rantai pasok | AI22: Implementasi rantai pasok | AJ22: Implementasi rantai pasok | AK22: Implementasi rantai pasok | AL22: Monitoring | AM22: Monitoring | AN22: Monitoring | AO22: Monitoring | AP22: Pending | AQ22: Planned | AS22: Schedule engagement with PLN on charging station infrastructure and potential Len role. | AT22: Need Follow Up
A23: 18 | B23: KLH / BPLH | C23: Battery waste & recycling | D23: 4 | E23: 3 | F23: 4 | G23: 3 | H23: =(D23*$B$56)+(E23*$B$57)+(F23*$B$58)+(G23*$B$59) -> 3.55 | I23: =IF(H23>=4.25,"P1",IF(H23>=3,"P2","P3")) -> P2 | J23: Hilir | K23: Lingkungan & Ekonomi Sirkular | L23: Permen LHK No. 9/2024 (Pengelolaan limbah baterai kendaraan listrik); Regulasi limbah B3 lainnya | M23: Pengumpulan, penyimpanan, daur ulang baterai, pengelolaan limbah B3, ekonomi sirkular | N23: Daur Ulang & Ekosistem Sirkular | O23: 9. Circular Economy & Recycling | Q23: Battery waste & recycling | R23: WS2 – Legal | S23: WS3 Innovation | T23: CTO | U23: Monitoring | V23: Support | W23: Recycling partner | X23: Circularity & compliance pathway | Z23: Audiensi | AA23: Audiensi | AB23: Regulasi baterai & daur ulang | AC23: Regulasi baterai & daur ulang | AD23: Requirement alignment | AE23: Finalisasi skema | AF23: Finalisasi skema | AG23: Finalisasi skema | AH23: Implementasi & pemantauan | AI23: Implementasi & pemantauan | AJ23: Implementasi & pemantauan | AK23: Implementasi & pemantauan | AL23: Monitoring | AM23: Monitoring | AN23: Monitoring | AO23: Monitoring | AP23: Pending | AQ23: Planned | AS23: Schedule engagement on battery waste, recycling and environmental/circularity requirements. | AT23: Need Follow Up
A24: 19 | B24: Kemendag | C24: Perdagangan / ekspor-impor | D24: 3 | E24: 4 | F24: 3 | G24: 3 | H24: =(D24*$B$56)+(E24*$B$57)+(F24*$B$58)+(G24*$B$59) -> 3.2 | I24: =IF(H24>=4.25,"P1",IF(H24>=3,"P2","P3")) -> P2 | J24: Enablers (Financing & Support) | K24: Fiskal, Perdagangan & Pembiayaan | L24: Ketentuan perdagangan/impor-ekspor | M24: Perdagangan, ekspor-impor, fasilitasi perdagangan | N24: Distribusi & Pasar | O24: 5. Sales, Distribution & Market; 8. Financing & Investment | Q24: Perdagangan / ekspor-impor | R24: WS2 – Legal | S24: WS1 Business Development; WS3 Supply Chain | T24: CMO | U24: Monitoring | V24: Accompany | W24: Partner input | X24: Trade / import-export pathway | Z24: Audiensi | AA24: Audiensi | AB24: Kebijakan ekspor-impor | AC24: Kebijakan ekspor-impor | AD24: Alignment | AE24: Fasilitasi perdagangan | AF24: Fasilitasi perdagangan | AG24: Fasilitasi perdagangan | AH24: Implementasi | AI24: Implementasi | AJ24: Implementasi | AK24: Implementasi | AL24: Monitoring | AM24: Monitoring | AN24: Monitoring | AO24: Monitoring | AP24: Pending | AQ24: Planned | AS24: Schedule engagement on trade/export-import policy and requirements relevant to MOLINAS. | AT24: Need Follow Up
A25: 20 | B25: OJK | C25: Financing ecosystem | D25: 4 | E25: 4 | F25: 4 | G25: 3 | H25: =(D25*$B$56)+(E25*$B$57)+(F25*$B$58)+(G25*$B$59) -> 3.75 | I25: =IF(H25>=4.25,"P1",IF(H25>=3,"P2","P3")) -> P2 | J25: Enablers (Financing & Support) | K25: Fiskal, Perdagangan & Pembiayaan | L25: POJK pembiayaan & leasing; Ketentuan pembiayaan konsumen/fleet, green financing | M25: Pembiayaan konsumen & fleet, skema leasing, green financing, market access | N25: Distribusi & Pasar; Pengguna & Layanan | O25: 5. Sales, Distribution & Market; 6. User, Service & After-Sales; 8. Financing & Investment | Q25: Financing ecosystem | R25: WS4 – Finance | S25: WS2 Legal; WS3 Market & Sales | T25: CFO | U25: Monitoring | V25: Co-Lead | W25: Optional | X25: Financing scheme & market readiness | Z25: Diskusi awal | AA25: Diskusi awal | AB25: Skema pembiayaan | AC25: Skema pembiayaan | AD25: Alignment pembiayaan | AE25: Finalisasi skema | AF25: Finalisasi skema | AG25: Finalisasi skema | AH25: Implementasi & market access | AI25: Implementasi & market access | AJ25: Implementasi & market access | AK25: Implementasi & market access | AL25: Monitoring | AM25: Monitoring | AN25: Monitoring | AO25: Monitoring | AP25: Pending | AQ25: Planned | AS25: Schedule engagement on financing ecosystem and relevant regulatory considerations. | AT25: Need Follow Up
A26: 21 | B26: BSN | C26: Standardisasi / SNI | D26: 4 | E26: 4 | F26: 4 | G26: 4 | H26: =(D26*$B$56)+(E26*$B$57)+(F26*$B$58)+(G26*$B$59) -> 4 | I26: =IF(H26>=4.25,"P1",IF(H26>=3,"P2","P3")) -> P2 | J26: Hulu | K26: Baterai & Teknologi Baterai; Chassis/Rangka & Komponen Kendaraan; Standardisasi | M26: Standardisasi, penyusunan/validasi SNI, conformity assessment | N26: Manufaktur & Supply Chain; Pengguna & Layanan | O26: 1. Engineering, Technology & R&D; 2. Raw Materials & Components; 3. Manufacturing & Assembly; 4. Supply Chain & Logistics; 6. User, Service & After-Sales | P26: Policy, Regulation & Standards; Technology, Data & Digital | Q26: Standardisasi / SNI | R26: WS2 – Ecosystem | S26: WS2 Legal; WS3 Innovation | T26: CTO | U26: Monitoring | V26: Support | W26: Technical input | X26: Standardization / SNI alignment | Z26: Audiensi | AA26: Audiensi | AB26: Standardisasi / SNI | AC26: Standardisasi / SNI | AD26: Alignment standar | AE26: Finalisasi standar | AF26: Finalisasi standar | AG26: Finalisasi standar | AH26: Conformity assessment & sertifikasi | AI26: Conformity assessment & sertifikasi | AJ26: Conformity assessment & sertifikasi | AK26: Conformity assessment & sertifikasi | AL26: Monitoring | AM26: Monitoring | AN26: Monitoring | AO26: Monitoring | AP26: Pending | AQ26: Planned | AS26: Schedule engagement on battery standardization/SNI, including the MOLINAS battery standardization workshop. | AT26: Need Follow Up
A27: 22 | B27: LSPro | C27: Sertifikasi | D27: 4 | E27: 4 | F27: 4 | G27: 4 | H27: =(D27*$B$56)+(E27*$B$57)+(F27*$B$58)+(G27*$B$59) -> 4 | I27: =IF(H27>=4.25,"P1",IF(H27>=3,"P2","P3")) -> P2 | J27: Hulu | K27: Baterai & Teknologi Baterai; Chassis/Rangka & Komponen Kendaraan. | L27: SNI baterai & keselamatan; SNI komponen kelistrikan; SNI kendaraan/rangka, rem, suspensi, dll. | M27: Conformity assessment, sertifikasi | N27: Manufaktur & Supply Chain; Pengguna & Layanan | O27: 1. Engineering, Technology & R&D; 2. Raw Materials & Components; 3. Manufacturing & Assembly; 4. Supply Chain & Logistics; 6. User, Service & After-Sales | P27: Policy, Regulation & Standards; Technology, Data & Digital | Q27: Sertifikasi | R27: WS2 – Ecosystem | S27: WS2 Legal; WS3 Innovation | T27: CTO | U27: Monitoring | V27: Support | W27: Technical input | X27: Sertifikasi | Z27: Audiensi | AA27: Audiensi | AB27: Standardisasi / SNI | AC27: Standardisasi / SNI | AD27: Alignment standar | AE27: Finalisasi standar | AF27: Finalisasi standar | AG27: Finalisasi standar | AH27: Conformity assessment & sertifikasi | AI27: Conformity assessment & sertifikasi | AJ27: Conformity assessment & sertifikasi | AK27: Conformity assessment & sertifikasi | AL27: Monitoring | AM27: Monitoring | AN27: Monitoring | AO27: Monitoring | AP27: Pending | AQ27: Planned | AS27: Schedule engagement on certification pathway and certification requirements. | AT27: Need Follow Up
A28: 23 | B28: Puslaik Kemhan | C28: Military qualification | D28: 4 | E28: 2 | F28: 4 | G28: 3 | H28: =(D28*$B$56)+(E28*$B$57)+(F28*$B$58)+(G28*$B$59) -> 3.35 | I28: =IF(H28>=4.25,"P1",IF(H28>=3,"P2","P3")) -> P2 | J28: Hilir | K28: Pertahanan & Strategic Use Case | L28: UU No. 16/2012 (Industri Pertahanan); standar/kebijakan kelaikan pertahanan | M28: Persyaratan sertifikasi dan kualifikasi militer, uji dan validasi | N28: Pengguna & Layanan | O28: 6. User, Service & After-Sales | P28: Policy, Regulation & Standards | Q28: Military qualification | R28: WS3 – Market & Sales | S28: WS3 Innovation; WS3 Market & Sales | T28: CTO | U28: Monitoring | V28: Accompany | W28: Technical input | X28: Military qualification pathway | Z28: Persyaratan sertifikasi | AA28: Persyaratan sertifikasi | AB28: Persyaratan sertifikasi | AC28: Proses sertifikasi | AD28: Certification plan | AE28: Uji & validasi | AF28: Uji & validasi | AG28: Uji & validasi | AH28: Sertifikasi & deployment | AI28: Sertifikasi & deployment | AJ28: Sertifikasi & deployment | AK28: Sertifikasi & deployment | AL28: Monitoring | AM28: Monitoring | AN28: Monitoring | AO28: Monitoring | AP28: Pending | AQ28: Planned | AS28: Schedule engagement on military qualification requirements for MOLINAS use cases. | AT28: Need Follow Up
A29: 24 | B29: Grab* | C29: Offtake / fleet | D29: 3 | E29: 4 | F29: 3 | G29: 3 | H29: =(D29*$B$56)+(E29*$B$57)+(F29*$B$58)+(G29*$B$59) -> 3.2 | I29: =IF(H29>=4.25,"P1",IF(H29>=3,"P2","P3")) -> P2 | J29: Hilir | K29: Pengguna / Offtaker | L29: Ketentuan operasional/fleet yang relevan | M29: Offtake, kebutuhan fleet, model bisnis, pilot dan implementasi fleet | N29: Pengguna & Layanan | O29: 5. Sales, Distribution & Market; 6. User, Service & After-Sales | P29: Policy, Regulation & Standards | Q29: Offtake / fleet | R29: WS3 – Market & Sales | S29: WS2 Ecosystem; WS3 Innovation | T29: CMO | U29: Monitoring | V29: Accompany | W29: OEM support | X29: Offtake / fleet demand | Z29: Diskusi kebutuhan awal | AA29: Diskusi kebutuhan awal | AB29: Diskusi kebutuhan awal | AC29: Kebutuhan fleet & model bisnis | AD29: Alignment komersial | AE29: Pilot / uji coba | AF29: Pilot / uji coba | AG29: Pilot / uji coba | AH29: Implementasi fleet | AI29: Implementasi fleet | AJ29: Implementasi fleet | AK29: Implementasi fleet | AL29: Monitoring | AM29: Monitoring | AN29: Monitoring | AO29: Monitoring | AP29: Pending | AQ29: Planned | AS29: Prioritize engagement with Grab to validate fleet/offtake requirements and potential demand. | AT29: Need Follow Up
A30: 25 | B30: Gojek* | C30: Offtake / fleet | D30: 3 | E30: 4 | F30: 3 | G30: 3 | H30: =(D30*$B$56)+(E30*$B$57)+(F30*$B$58)+(G30*$B$59) -> 3.2 | I30: =IF(H30>=4.25,"P1",IF(H30>=3,"P2","P3")) -> P2 | J30: Hilir | K30: Pengguna / Offtaker | L30: Ketentuan operasional/fleet yang relevan | M30: Offtake, kebutuhan fleet, model bisnis, pilot dan implementasi fleet | N30: Pengguna & Layanan | O30: 5. Sales, Distribution & Market; 6. User, Service & After-Sales | P30: Policy, Regulation & Standards | Q30: Offtake / fleet | R30: WS3 – Market & Sales | S30: WS2 Ecosystem; WS3 Innovation | T30: CMO | U30: Monitoring | V30: Accompany | W30: OEM support | X30: Offtake / fleet demand | Z30: Diskusi kebutuhan awal | AA30: Diskusi kebutuhan awal | AB30: Diskusi kebutuhan awal | AC30: Kebutuhan fleet & model bisnis | AD30: Alignment komersial | AE30: Pilot / uji coba | AF30: Pilot / uji coba | AG30: Pilot / uji coba | AH30: Implementasi fleet | AI30: Implementasi fleet | AJ30: Implementasi fleet | AK30: Implementasi fleet | AL30: Monitoring | AM30: Monitoring | AN30: Monitoring | AO30: Monitoring | AP30: Pending | AQ30: Planned | AS30: Prioritize engagement with Gojek to validate fleet/offtake requirements and potential demand. | AT30: Need Follow Up
A31: 26 | B31: Pos Indonesia | C31: Commercial fleet | D31: 3 | E31: 4 | F31: 3 | G31: 3 | H31: =(D31*$B$56)+(E31*$B$57)+(F31*$B$58)+(G31*$B$59) -> 3.2 | I31: =IF(H31>=4.25,"P1",IF(H31>=3,"P2","P3")) -> P2 | J31: Enablers (Logistics & SDM) | K31: Pengguna / Offtaker | L31: Ketentuan operasional/fleet yang relevan | M31: Kebutuhan armada, pilot fleet, deployment komersial | N31: Pengguna & Layanan | O31: 5. Sales, Distribution & Market; 6. User, Service & After-Sales | P31: Human Capital & Capability | Q31: Commercial fleet | R31: WS3 – Market & Sales | S31: WS2 Ecosystem; WS4 Finance, WS3 Supply Chain | T31: CMO | U31: Monitoring | V31: Accompany | W31: OEM support | X31: Fleet deployment | Z31: Diskusi kebutuhan awal | AA31: Diskusi kebutuhan awal | AB31: Diskusi kebutuhan awal | AC31: Kebutuhan armada | AD31: Alignment deployment | AE31: Pilot fleet | AF31: Pilot fleet | AG31: Pilot fleet | AH31: Deployment awal | AI31: Deployment awal | AJ31: Deployment awal | AK31: Deployment awal | AL31: Monitoring | AM31: Monitoring | AN31: Monitoring | AO31: Monitoring | AP31: Pending | AQ31: Planned | AS31: Engage Pos Indonesia to validate commercial fleet requirements and potential deployment. | AT31: Need Follow Up
A32: 27 | B32: JNE | C32: Commercial fleet | D32: 3 | E32: 4 | F32: 3 | G32: 3 | H32: =(D32*$B$56)+(E32*$B$57)+(F32*$B$58)+(G32*$B$59) -> 3.2 | I32: =IF(H32>=4.25,"P1",IF(H32>=3,"P2","P3")) -> P2 | J32: Enablers (Logistics & SDM) | K32: Pengguna / Offtaker | L32: Ketentuan operasional/fleet yang relevan | M32: Kebutuhan armada, pilot fleet, deployment komersial | N32: Pengguna & Layanan | O32: 5. Sales, Distribution & Market; 6. User, Service & After-Sales | P32: Human Capital & Capability | Q32: Commercial fleet | R32: WS3 – Market & Sales | S32: WS2 Ecosystem; WS4 Finance, WS3 Supply Chain | T32: CMO | U32: Monitoring | V32: Accompany | W32: OEM support | X32: Fleet deployment | Z32: Diskusi kebutuhan awal | AA32: Diskusi kebutuhan awal | AB32: Diskusi kebutuhan awal | AC32: Kebutuhan armada | AD32: Alignment deployment | AE32: Pilot fleet | AF32: Pilot fleet | AG32: Pilot fleet | AH32: Deployment awal | AI32: Deployment awal | AJ32: Deployment awal | AK32: Deployment awal | AL32: Monitoring | AM32: Monitoring | AN32: Monitoring | AO32: Monitoring | AP32: Pending | AQ32: Planned | AS32: Engage JNE to validate commercial fleet requirements and potential deployment. | AT32: Need Follow Up
A33: 28 | B33: AESMOLI | C33: Industry association / ecosystem coordination | D33: 3 | E33: 4 | F33: 3 | G33: 3 | H33: =(D33*$B$56)+(E33*$B$57)+(F33*$B$58)+(G33*$B$59) -> 3.2 | I33: =IF(H33>=4.25,"P1",IF(H33>=3,"P2","P3")) -> P2 | J33: Hilir | K33: Industry association / ecosystem coordination | M33: Koordinasi pelaku industri, penyampaian masukan kebijakan, alignment kebutuhan industri, serta penguatan kolaborasi ekosistem | N33: Semua Tahap (Ekosistem) | O33: Perlu validasi | P33: Policy, Regulation & Standards | Q33: Industry alignment, policy input & ecosystem coordination | R33: WS2 – Ecosystem | S33: WS1 Business Development; WS3 Innovation & Market | T33: CMO | U33: Monitoring | V33: Accompany | W33: Partner / OEM | X33: Industry alignment, policy input & ecosystem collaboration | Z33: Audiensi / engagement awal | AA33: Audiensi / engagement awal | AB33: Industry input & policy discussion | AC33: Industry input & policy discussion | AD33: Alignment program | AE33: Alignment program | AF33: Alignment program | AG33: Alignment program | AH33: Koordinasi implementasi | AI33: Koordinasi implementasi | AJ33: Koordinasi implementasi | AK33: Koordinasi implementasi | AL33: Monitoring | AM33: Monitoring | AN33: Monitoring | AO33: Monitoring | AP33: Pending | AQ33: Planned | AS33: Continue industry alignment and policy discussion; validate AESMOLI role and concrete engagement scope. | AT33: Need Follow Up
A34: 29 | B34: Mitra terkait* | C34: Model bisnis / struktur kemitraan | D34: 3 | E34: 4 | F34: 3 | G34: 3 | H34: =(D34*$B$56)+(E34*$B$57)+(F34*$B$58)+(G34*$B$59) -> 3.2 | I34: =IF(H34>=4.25,"P1",IF(H34>=3,"P2","P3")) -> P2 | J34: Hulu | K34: Business Model / Partnership | L34: Regulasi korporasi, investasi, pembiayaan dan partnership yang relevan | M34: Struktur kemitraan, commercial model validation | N34: Semua Tahap (Ekosistem) | O34: Perlu validasi | Q34: Model bisnis / struktur kemitraan | R34: WS1 – Business Development | S34: WS3 Market & Sales, Innovation; WS2 Legal/Ecosystem | T34: CMO | U34: Monitoring | V34: Co-Lead | W34: Partner input | X34: Commercial model validation | Y34: Partner mapping & engagement setup | Z34: Audiensi / engagement awal | AA34: Audiensi / engagement awal | AB34: Diskusi kebutuhan awal | AC34: Alignment kebutuhan fleet / armada | AD34: Alignment komersial / deployment | AE34: Koordinasi uji coba | AF34: Koordinasi uji coba | AG34: Koordinasi uji coba | AH34: Koordinasi implementasi fleet / deployment | AI34: Koordinasi implementasi fleet / deployment | AJ34: Koordinasi implementasi fleet / deployment | AK34: Koordinasi implementasi fleet / deployment | AL34: Monitoring | AM34: Monitoring | AN34: Monitoring | AO34: Monitoring | AP34: Pending | AQ34: Planned | AS34: Identify the specific partner entity and schedule engagement to validate business model and partnership structure. | AT34: Need Follow Up
A35: 30 | B35: ATMI | C35: Manufaktur & Supply Chain | D35: 4 | E35: 4 | F35: 4 | G35: 4 | H35: =(D35*$B$56)+(E35*$B$57)+(F35*$B$58)+(G35*$B$59) -> 4 | I35: =IF(H35>=4.25,"P1",IF(H35>=3,"P2","P3")) -> P2 | J35: Midstream | K35: Mold Making, Plastic Injection, Product Development & Vocational Education | L35: Permenkominfo No. 3/2024 (Sertifikasi alat/perangkat telekomunikasi); SNI, standar komunikasi kendaraan | M35: Tool making, plastic injection, product development, scientific molding, mold assembly, training/certification, capacity building untuk mendukung MOLINAS | N35: Manufaktur & Supply Chain; Pengguna & Layanan | O35: 3. Manufacturing & Assembly; 4. Supply Chain & Logistics; 6. User, Service & After-Sales | P35: Human Capital & Capability | Q35: Design enhancement & mass-production preparation | R35: WS2 – Ecosystem | S35: WS3 – Innovation, Supply Chain; WS2 – Legal | T35: CTO / CMO | U35: Monitoring | V35: Co-Lead | W35: Technical / vocational partner | X35: Readiness mold & plastic injection, capacity building, training, dan industrial ecosystem support | Z35: Audiensi | AA35: Audiensi | AB35: Scope alignment | AC35: Capability validation | AD35: Capability validation | AE35: Program design | AF35: Program design | AG35: Implementation preparation | AH35: Implementation | AI35: Implementation | AJ35: Implementation | AK35: Readiness review | AL35: Readiness review | AM35: Evaluation | AN35: Evaluation | AO35: Evaluation | AP35: Pending | AQ35: Planned | AS35: Schedule engagement to align scope for design enhancement, mold/plastic injection readiness, training and mass-production preparation. | AT35: Need Follow Up
A36: 31 | B36: Adyawinsa Group | C36: Manufaktur & Supply Chain | D36: 5 | E36: 4 | F36: 3 | G36: 4 | H36: =(D36*$B$56)+(E36*$B$57)+(F36*$B$58)+(G36*$B$59) -> 4.05 | I36: =IF(H36>=4.25,"P1",IF(H36>=3,"P2","P3")) -> P2 | J36: Midstream | K36: Design & Engineering; Frame & Chassis; Plastic Injection; Electrical & Power; Mass Production | L36: Permenkominfo No. 3/2024 (Sertifikasi alat/perangkat telekomunikasi); SNI, standar komunikasi kendaraan | M36: Design enhancement, FMEA, engineering, detailed BOM/process, production line & plant readiness, component sourcing, frame/chassis, plastic injection, electrical & power, quality assurance, dan mass-production preparation | N36: Manufaktur & Supply Chain; Distribusi & Pasar | O36: 1. Engineering, Technology & R&D; 3. Manufacturing & Assembly; 4. Supply Chain & Logistics; 5. Sales, Distribution & Market | R36: WS3 – Innovation | S36: WS2 – Ecosystem; WS1 – Business Development | T36: CTO / COO | U36: Monitoring | V36: Co-Lead | W36: Manufacturing / engineering partner | X36: Design & engineering readiness, supply-chain support, plant readiness, dan mass-production pathway | Z36: Audiensi | AA36: Audiensi | AB36: Design enhancement | AC36: Design enhancement | AD36: Engineering / FMEA | AE36: Engineering / FMEA | AF36: Engineering GO | AG36: Tooling & production preparation | AH36: Tooling & production preparation | AI36: Trial / product verification | AJ36: Trial / quality approval | AK36: Mass-production preparation | AL36: Mass-production preparation | AM36: Readiness review | AN36: Readiness review | AO36: Evaluation | AP36: Pending | AQ36: Planned | AR36: 46290 | AS36: Conduct scheduled visit with Matius – Adyawinsa and capture follow-up actions. | AT36: Active
A37: 32 | B37: Komdigi | C37: Connectivity / IoT | D37: 2 | E37: 2 | F37: 2 | G37: 2 | H37: =(D37*$B$56)+(E37*$B$57)+(F37*$B$58)+(G37*$B$59) -> 2 | I37: =IF(H37>=4.25,"P1",IF(H37>=3,"P2","P3")) -> P3 | J37: Enablers (Technology, Data & Digital) | K37: Konektivitas & Digital | L37: Permenkominfo No. 3/2024 (Sertifikasi alat/perangkat telekomunikasi); SNI, standar komunikasi kendaraan | M37: IoT/TCU, GPS, 4G/5G, perangkat komunikasi, keamanan data, standardisasi | N37: Pengguna & Layanan | O37: 6. User, Service & After-Sales | P37: Policy, Regulation & Standards; Technology, Data & Digital | Q37: Pengembangan ekosistem mold making, plastic injection & vocational capacity | R37: WS3 – Innovation | S37: WS2 Legal | T37: CTO | U37: Monitoring | V37: Support | W37: Technology partner | X37: Digital/connectivity compliance | Z37: Audiensi | AA37: Audiensi | AB37: Diskusi IoT/TCU & standar | AC37: Diskusi IoT/TCU & standar | AD37: Alignment teknis | AE37: Pilot & integrasi | AF37: Pilot & integrasi | AG37: Pilot & integrasi | AH37: Implementasi (jika relevan) | AI37: Implementasi (jika relevan) | AJ37: Implementasi (jika relevan) | AK37: Implementasi (jika relevan) | AL37: Monitoring | AM37: Monitoring | AN37: Monitoring | AO37: Monitoring | AP37: Pending | AQ37: Planned | AS37: Schedule engagement on digital/connectivity ecosystem, including mold making, plastic injection and vocational capacity. | AT37: Need Follow Up
A42: MOLINAS PROGRAM MILESTONES
A43: Agt W1 | B43: Program Mobilization & Stakeholder Mapping
A44: Sep W4 | B44: Regulatory Clarity & Key Decision Closure
...

Sheet KRITERIA PRIORITAS (SCORING)
A1: KRITERIA PENILAIAN & SCORING PRIORITAS WS2
A2: Penilaian menggunakan skala 1–5; setiap score dikalikan bobot kriteria untuk memperoleh Priority Score.
A4: Priority Score = (Criticality × 30%) + (Program Dependency × 25%) + (Urgency × 25%) + (Breadth of Impact × 20%)
A6: Kriteria | B6: Bobot | C6: Definisi Kriteria | D6: 1 – Sangat Rendah | E6: 2 – Rendah | F6: 3 – Menengah | G6: 4 – Tinggi | H6: 5 – Sangat Tinggi
A7: Criticality | B7: 0.3 | C7: Mengukur tingkat keparahan konsekuensi apabila stakeholder/regulasi tidak tertangani terhadap keberhasilan program. | D7: Konsekuensi sangat terbatas; tidak memengaruhi aktivitas utama, milestone, atau target program dan dapat ditangani melalui proses rutin. | E7: Gangguan terbatas pada aktivitas tertentu; tidak berdampak signifikan terhadap milestone utama dan masih mudah dimitigasi. | F7: Dampak material pada satu atau beberapa aktivitas penting; membutuhkan koordinasi/mitigasi aktif, namun masih dapat dipulihkan. | G7: Berpotensi mengganggu milestone kritis atau menimbulkan keterlambatan berantai; membutuhkan intervensi lintas pihak yang signifikan. | H7: Berpotensi menghentikan aktivitas fundamental, menggagalkan mandatory requirement/approval, atau menyebabkan target utama tidak tercapai; ruang recovery sangat terbatas.
